[2024-03-29T20:11:51.159+0000] {taskinstance.py:1979} INFO - Dependencies all met for dep_context=non-requeueable deps ti=<TaskInstance: spotify_test00.transform_data manual__2024-03-29T20:11:45.971067+00:00 [queued]>
[2024-03-29T20:11:51.167+0000] {taskinstance.py:1979} INFO - Dependencies all met for dep_context=requeueable deps ti=<TaskInstance: spotify_test00.transform_data manual__2024-03-29T20:11:45.971067+00:00 [queued]>
[2024-03-29T20:11:51.167+0000] {taskinstance.py:2193} INFO - Starting attempt 1 of 1
[2024-03-29T20:11:51.180+0000] {taskinstance.py:2214} INFO - Executing <Task(PythonOperator): transform_data> on 2024-03-29 20:11:45.971067+00:00
[2024-03-29T20:11:51.186+0000] {standard_task_runner.py:60} INFO - Started process 1180 to run task
[2024-03-29T20:11:51.188+0000] {standard_task_runner.py:87} INFO - Running: ['***', 'tasks', 'run', 'spotify_test00', 'transform_data', 'manual__2024-03-29T20:11:45.971067+00:00', '--job-id', '143', '--raw', '--subdir', 'DAGS_FOLDER/dag_spotify_test.py', '--cfg-path', '/tmp/tmpepsbftuz']
[2024-03-29T20:11:51.190+0000] {standard_task_runner.py:88} INFO - Job 143: Subtask transform_data
[2024-03-29T20:11:51.220+0000] {task_command.py:423} INFO - Running <TaskInstance: spotify_test00.transform_data manual__2024-03-29T20:11:45.971067+00:00 [running]> on host 5eb6f8f434b5
[2024-03-29T20:11:51.343+0000] {taskinstance.py:2510} INFO - Exporting env vars: AIRFLOW_CTX_DAG_OWNER='***' AIRFLOW_CTX_DAG_ID='spotify_test00' AIRFLOW_CTX_TASK_ID='transform_data' AIRFLOW_CTX_EXECUTION_DATE='2024-03-29T20:11:45.971067+00:00' AIRFLOW_CTX_TRY_NUMBER='1' AIRFLOW_CTX_DAG_RUN_ID='manual__2024-03-29T20:11:45.971067+00:00'
[2024-03-29T20:11:51.344+0000] {taskinstance.py:2728} ERROR - Task failed with exception
Traceback (most recent call last):
  File "/home/airflow/.local/lib/python3.8/site-packages/airflow/models/taskinstance.py", line 444, in _execute_task
    result = _execute_callable(context=context, **execute_callable_kwargs)
  File "/home/airflow/.local/lib/python3.8/site-packages/airflow/models/taskinstance.py", line 414, in _execute_callable
    return execute_callable(context=context, **execute_callable_kwargs)
  File "/home/airflow/.local/lib/python3.8/site-packages/airflow/operators/python.py", line 200, in execute
    return_value = self.execute_callable()
  File "/home/airflow/.local/lib/python3.8/site-packages/airflow/operators/python.py", line 217, in execute_callable
    return self.python_callable(*self.op_args, **self.op_kwargs)
TypeError: transform_api() takes 0 positional arguments but 2 were given
[2024-03-29T20:11:51.351+0000] {taskinstance.py:1149} INFO - Marking task as FAILED. dag_id=spotify_test00, task_id=transform_data, execution_date=20240329T201145, start_date=20240329T201151, end_date=20240329T201151
[2024-03-29T20:11:51.498+0000] {standard_task_runner.py:107} ERROR - Failed to execute job 143 for task transform_data (transform_api() takes 0 positional arguments but 2 were given; 1180)
[2024-03-29T20:11:51.520+0000] {local_task_job_runner.py:234} INFO - Task exited with return code 1
[2024-03-29T20:11:51.532+0000] {taskinstance.py:3309} INFO - 0 downstream tasks scheduled from follow-on schedule check
